Workbook
Name _3._Document: '[1]1.Global Setting'!#REF!
Name _3._Document: '[1]1.Global Setting'!#REF!
Name _4._Cost_center___Profit_Center: '[1]1.Global Setting'!#REF!
Name _4._Cost_center___Profit_Center: '[1]1.Global Setting'!#REF!
Name _5._Tax: '[1]1.Global Setting'!#REF!
Name _5._Tax: '[1]1.Global Setting'!#REF!
Name ☞: '[2]1.Global Setting'!#REF!
Name ☞: '[2]1.Global Setting'!#REF!
Name a: #REF!
Name a: #REF!
Name application: #REF!
Name application: #REF!
Name ETC: #REF!
Name ETC: #REF!
Name flow: #REF!
Name flow: #REF!
Name head: #REF!
Name head: #REF!
Name Keetsa_Pillows: '[4]Materials List'!#REF!
Name Keetsa_Pillows: '[4]Materials List'!#REF!
Name kmart: '[5]Materials List'!#REF!
Name kmart: '[5]Materials List'!#REF!
Name kmart: '[6]Materials List'!#REF!
Name MARK: '[4]Materials List'!#REF!
Name MARK: '[4]Materials List'!#REF!
Name MARK2: #REF!
Name MARK2: #REF!
Name RATE1: '[7]WMT-150Q'!$F$13
Name tony: #REF!
Name tony: #REF!
Name twort000: '[1]1.Global Setting'!$AB$66
Name ZIPPERB: #N/A
Name 暗暗: [8]负债表!$G$1

Sheet CM
A1: CONTAINER MANIFEST
J2: PAGE.1
A3: SHIPPER: PT. Zinus Global Indonesia
A4: CONSIGNEE: ZINUS,INC (USA)
A5: CONTAINER NO. | D5: CONTAINER SIZE: | E5: SEAL NO. | G5: SHIPPING LINE
D6: 20' 40'S 40RH 40'H 45'
D7: [ ] [ X ] [ ] [ ] [ ]
A8: VESSEL / VOY. | D8: LOADING PORT | E8: DISCHARGE PORT / DESTINATION | G8: SAILING DATE | J8: ARRIVAL DATE
D9: JAKARTA, INDONESIA | E9: =#REF! -> #REF! | G9: JULY. XX, 2019 | J9: AUGT. XX, 2019
A11: PURCHASE ORDER NO. | B11: STYLE NO | C11: UPC NO | D11: BRIEF DESCRIPTION | E11: NO. OF | F11: MEASUREMENT | G11: GROSS WEIGHT | H11: Quantity | I11: SAMPLE | J11: B/L NO.
E12: CARTONS | F12: CBM | G12: KGS | H12: PCS | I12: CTN. NO.
A13: =#REF! -> #REF! | B13: XX | C13: =#REF! -> #REF! | D13: =#REF! -> #REF! | E13: =#REF! -> #REF! | F13: 58.344 | G13: 6342.7 | H13: =E13 -> #REF!
D15: TOTAL:
A16: SHIPPER'S CO. CHOP &
A17: AUTHORIZED SIGNATURE:
A19: PO DATE : MAY. XX,2019
A20: ETD : JULY. XX,2019

Sheet CI
B2: COMMERCIAL INVOICE
B3: Seller : | I3: Invoice No. and Date
B4: PT.ZINUS DREAM INDONESIA | I4: ID2608-9295 | M4: August 28 2026
B5: JL. RAYA SERANG KM. 12 RT. 01 RW. 05, KP. GEBANG | I5: L/C No. and Date
B6: DESA/KEL. SUKADAMAI, KEC. CIKUPA, | I6: T/T PAYMENT
B7: KAB. TANGERANG BANTEN
B9: Consignee : | I9: Buyer (if other than consignee)
B10: ZINUS, INC. | I10: ZINUS INC,
B11: 5731 PROMONTORY PARKWAY, | I11: 8F, 10 (AMIGO-TOWER) YATAP-RO,
B12: TRACY, CA 95377, USA | I12: 81 BEON-GIL BUNDANG-GU, SEONGNAM-SI, GYUNGGI-DO, 13497, SOUTH KOREA
B14: Notify : | I14: Other Reference
B15: ZINUS, INC. | I15: *COUNTRY OF ORIGIN : INDONESIA
B16: 5731 PROMONTORY PARKWAY, | I16: PO# | J16: TIN60185
B17: TRACY, CA 95377, USA | I17: DO# | J17: 080600452114
I18: BL# | J18: EGLV080600452114
B20: Departure Date : | I20: Terms of delivery and payment
B21: 46271 | I21: *FOB INDONESIA
B22: Vessel / Flight / Voyage : | F22: From / Port Of Loading : | I22: *AT 90 DAYS AFTER B/L DATE
B23: EVER BOOMY 1206-093A | F23: Jakarta, INDONESIA | I23: *FOAM MATTRESS, HYBRID MATTRESS, SPRING MATTRESS
B24: To : | C24: OAKLAND,CA
B25: =Shipping Mark=
B27: HS CODE | C27: PO# | E27: ITEM# | F27: F CODE | G27: DESCRIPTION | J27: Quantity | L27: Unit Price | M27: Amount | N27: Total NW
B29: 9404.21.20 | C29: TIN60185 | E29: ZU-MFGN5OZI-12Q | F29: F.MFG.12Q.012.ZU | G29: ZINUS 12IN COOLING GREEN TEA MEMORY FOAM MATTRESS QUEEN | J29: 20 | K29: PCS | L29: 105.81 | M29: =L29*J29 -> 2116.2 | N29: =' PL'!J31 -> 751.2
B30: 9404.21.20 | C30: TIN60185 | E30: ZU-MFGN5PZI-12K | F30: F.MFG.12K.013.ZU | G30: ZINUS 12IN ULTRA COOLING GREEN TEA MEMORY FOAM MATTRESS KING | J30: 113 | K30: PCS | L30: 164.94 | M30: =L30*J30 -> 18638.22 | N30: =' PL'!J32 -> 5619.49
B31: 9404.21.20 | C31: TIN60185 | E31: ZU-MFGN5PZI-12Q | F31: F.MFG.12Q.013.ZU | G31: ZINUS 12IN ULTRA COOLING GREEN TEA MEMORY FOAM MATTRESS QUEEN | J31: 20 | K31: PCS | L31: 136.81 | M31: =L31*J31 -> 2736.2 | N31: =' PL'!J33 -> 789.2
B32: 9404.90.00 | C32: TIN60185 | E32: MF-TGTNM1ZI-03K | F32: F.TGT.03K.001.ZU | G32: 3IN Sleepy's Gel Memory Foam Topper King | J32: 60 | K32: PCS | L32: 46.52 | M32: =L32*J32 -> 2791.2 | N32: =' PL'!J34 -> 586.8
B33: 9404.29.10 | C33: TIN60185 | E33: ZU-MSHPHMZI-14Q | F33: F.MSH.14Q.000.ZU | G33: 14in Plush Hybrid Mattress | J33: 20 | K33: PCS | L33: 93.06 | M33: =L33*J33 -> 1861.2 | N33: =' PL'!J35 -> 924.82
B34: 9404.29.10 | C34: TIN60185 | E34: ZU-MSHQ5OZI-12Q | F34: F.MSH.12Q.024.ZU | G34: Zinus 12in Cooling Green Tea Hybrid Queen | J34: 38 | K34: PCS | L34: 123.82 | M34: =L34*J34 -> 4705.16 | N34: =' PL'!J36 -> 1761.3
I52: TOTAL : | J52: =SUM(J29:J51) -> 271 | K52: PCS | M52: =SUM(M29:M51) -> 32848.18 | N52: =SUM(N29:N51) -> 10432.81
C54: **REMARK**
C55: WE DECLARE THAT THE SHIPMENT CONTAINS NO
C56: SOLID WOOD PACKING MATERIALS.
K75: Signed by,

Sheet  PL
B2: PACKING LIST
B3: Shipper | H3: Invoice No. and Date
B4: =CI!B4 -> PT.ZINUS DREAM INDONESIA | H4: =CI!I4 -> ID2608-9295 | J4: =CI!M4 -> August 28 2026
B5: =CI!B5 -> JL. RAYA SERANG KM. 12 RT. 01 RW. 05, KP. GEBANG | H5: L/C No. and Date
B6: =CI!B6 -> DESA/KEL. SUKADAMAI, KEC. CIKUPA, | H6: =CI!I6 -> T/T PAYMENT
B7: =CI!B7 -> KAB. TANGERANG BANTEN
B9: Consignee : | H9: Buyer (if other than consignee)
B10: =CI!B10 -> ZINUS, INC. | H10: =CI!I10 -> ZINUS INC,
B11: =CI!B11 -> 5731 PROMONTORY PARKWAY, | H11: =CI!I11 -> 8F, 10 (AMIGO-TOWER) YATAP-RO,
B12: =CI!B12 -> TRACY, CA 95377, USA | H12: =CI!I12 -> 81 BEON-GIL BUNDANG-GU, SEONGNAM-SI, GYUNGGI-DO, 13497, SOUTH KOREA
B14: Notify : | H14: Other Reference
B15: =CI!B15 -> ZINUS, INC. | H15: *COUNTRY OF ORIGIN : INDONESIA
B16: =CI!B16 -> 5731 PROMONTORY PARKWAY, | H16: PO# | I16: =CI!J16 -> TIN60185
B17: =CI!B17 -> TRACY, CA 95377, USA | H17: DO# | I17: =CI!J17 -> 080600452114
H18: BL# | I18: =CI!J18 -> EGLV080600452114
B20: Departure Date : | H20: Terms of delivery and payment
B21: =CI!B21 -> 46271 | H21: =CI!I21 -> *FOB INDONESIA | XFA21: =SUM(B21:XEZ21) -> 46271
B22: Vessel / Flight / Voyage : | E22: From / Port Of Loading : | H22: =CI!I22 -> *AT 90 DAYS AFTER B/L DATE
B23: =CI!B23 -> EVER BOOMY 1206-093A | E23: Jakarta, INDONESIA | H23: =CI!I23 -> *FOAM MATTRESS, HYBRID MATTRESS, SPRING MATTRESS
B24: To : | C24: =CI!C24 -> OAKLAND,CA
B26: = Shipping MARK | D26: No. & Kind of Pkgs; Goods Description | G26: Net Weight | I26: Gross Weight | J26: Measurement
G28: =J52 -> 10432.81 | I28: 11392.53 | J28: 52.315
C30: PO# | D30: DESCRIPTION | F30: QTY | I30: NW/PCS | J30: Total NW
C31: =CI!C29 -> TIN60185 | D31: =CI!G29 -> ZINUS 12IN COOLING GREEN TEA MEMORY FOAM MATTRESS QUEEN | F31: =CI!J29 -> 20 | G31: =F31 -> 20 | I31: 37.56 | J31: =I31*G31 -> 751.2 | XFA31: =SUM(B31:XEZ31) -> 828.76
C32: =CI!C30 -> TIN60185 | D32: =CI!G30 -> ZINUS 12IN ULTRA COOLING GREEN TEA MEMORY FOAM MATTRESS KING | F32: =CI!J30 -> 113 | G32: =F32 -> 113 | I32: 49.73 | J32: =I32*G32 -> 5619.49 | XFA32: =SUM(B32:XEZ32) -> 5895.22
C33: =CI!C31 -> TIN60185 | D33: =CI!G31 -> ZINUS 12IN ULTRA COOLING GREEN TEA MEMORY FOAM MATTRESS QUEEN | F33: =CI!J31 -> 20 | G33: =F33 -> 20 | I33: 39.46 | J33: =I33*G33 -> 789.2 | XFA33: =SUM(B33:XEZ33) -> 868.66
C34: =CI!C32 -> TIN60185 | D34: =CI!G32 -> 3IN Sleepy's Gel Memory Foam Topper King | F34: =CI!J32 -> 60 | G34: =F34 -> 60 | I34: 9.78 | J34: =I34*G34 -> 586.8 | XFA34: =SUM(B34:XEZ34) -> 716.58
C35: =CI!C33 -> TIN60185 | D35: =CI!G33 -> 14in Plush Hybrid Mattress | F35: =CI!J33 -> 20 | G35: =F35 -> 20 | I35: 46.241 | J35: =I35*G35 -> 924.82 | XFA35: =SUM(B35:XEZ35) -> 1011.061
C36: =CI!C34 -> TIN60185 | D36: =CI!G34 -> Zinus 12in Cooling Green Tea Hybrid Queen | F36: =CI!J34 -> 38 | G36: =F36 -> 38 | I36: 46.35 | J36: =I36*G36 -> 1761.3 | XFA36: =SUM(B36:XEZ36) -> 1883.65
XFA37: =SUM(B37:XEZ37) -> 0
E52: TOTAL : | F52: =SUM(F31:F51) -> 271 | G52: =SUM(G31:G51) -> 271 | J52: =SUM(J31:J51) -> 10432.81 | XFA52: =SUM(B52:XEZ52) -> 10974.81
I74: Signed by,
C76: WE DECLARE THAT THE SHIPMENT CONTAINS NO SOLID WOOD PACKING MATERIALS.

Sheet SHIPPING MARK
C1: =SHIPPING MARK ATTACHMENT=
D5: PO No.:
D6: Supplier Stock# :
D7: Desc: FOAM MATTRESS
D8: Shipping Case Qty. :
D9: Made In Indonesia
D10: Shipping Case# : of

Sheet SN
A1: PT ZINUS GLOBAL INDONESIA
A2: Jl Raya Parung No. 68
A3: Kel. Curug, Kec. Gunung Sindur, Kab. Bogor
A4: Prop. Jawa Barat, Indonesia
E9: =CI!I4 -> ID2608-9295
A10: Messrs. | B10: ZINUS INC.
B11: 8F, 10 (AMIGO-TOWER) YATAP-RO, GYUNGGI-DO, KOREA
B12: 81 BEON-GIL, BUNDANG-GU, SEONGNAM-SI,
B13: GYUNGGI-DO, KOREA
A15: Seller : PT ZINUS GLOBAL INDONEISA as Selle hereby confirm having sold to you the following goods by contract of sale made on the above date and on the terms and
A16: conditions hereinafter set forth. The buyer is hereby requested to sign and return the original attached hereto, and if any discrepancy
A17: by found by the Buyer the Seller should be informed immediately by cable or telex as well as supplying complete evidences in full detail fro
A18: the status of merchandise in deffective status by writing.
A20: Time of Delivery | B20: -
A21: Terms of Payment | B21: =CI!I22 -> *AT 90 DAYS AFTER B/L DATE | C21: Port of Shipment | E21: INDONESIA
A22: Place of Delivery | B22: FOB INDONESIA | C22: Destination | E22: USA Port
A23: Country of Origin | B23: P.R. of INDONESIA
A24: Remarks | B24: LC shall be opened by Banker's Usance terms.
A25: HTS CODE | B25: Item No. & Description | C25: Quantity | F25: Unit price | G25: Amount
A28: =CI!B29 -> 9404.21.20 | B28: =CI!H29 -> 0 | C28: =CI!C29 -> TIN60185 | D28: =CI!K29 -> PCS | E28: PCS | F28: =CI!M29 -> 2116.2 | G28: =CI!N29 -> 751.2
A29: =CI!B30 -> 9404.21.20 | B29: =CI!H30 -> 0 | C29: =CI!C30 -> TIN60185 | D29: =CI!K30 -> PCS | E29: PCS | F29: =CI!M30 -> 18638.22 | G29: =CI!N30 -> 5619.49
A30: =CI!B31 -> 9404.21.20 | B30: =CI!H31 -> 0 | C30: =CI!C31 -> TIN60185 | D30: =CI!K31 -> PCS | E30: PCS | F30: =CI!M31 -> 2736.2 | G30: =CI!N31 -> 789.2
A31: =CI!B37 -> 0 | B31: =CI!H37 -> 0 | C31: =CI!C37 -> 0 | D31: =CI!K37 -> 0 | E31: PCS | F31: =CI!M37 -> 0 | G31: =CI!N37 -> 0
A32: =CI!#REF! -> #REF! | B32: =CI!#REF! -> #REF! | C32: =CI!#REF! -> #REF! | D32: =CI!#REF! -> #REF! | E32: PCS | F32: =CI!#REF! -> #REF! | G32: =CI!#REF! -> #REF!
A33: =CI!#REF! -> #REF! | B33: =CI!#REF! -> #REF! | C33: =CI!#REF! -> #REF! | D33: =CI!#REF! -> #REF! | E33: PCS | F33: =CI!#REF! -> #REF! | G33: =CI!#REF! -> #REF!
A34: =CI!#REF! -> #REF! | B34: =CI!#REF! -> #REF! | C34: =CI!#REF! -> #REF! | D34: =CI!#REF! -> #REF! | E34: PCS | F34: =CI!#REF! -> #REF! | G34: =CI!#REF! -> #REF!
A35: =CI!#REF! -> #REF! | B35: =CI!#REF! -> #REF! | C35: =CI!#REF! -> #REF! | D35: =CI!#REF! -> #REF! | E35: PCS | F35: =CI!#REF! -> #REF! | G35: =CI!#REF! -> #REF!
A36: =CI!#REF! -> #REF! | B36: =CI!#REF! -> #REF! | C36: =CI!#REF! -> #REF! | D36: =CI!#REF! -> #REF! | E36: PCS | F36: =CI!#REF! -> #REF! | G36: =CI!#REF! -> #REF!
A37: =CI!#REF! -> #REF! | B37: =CI!#REF! -> #REF! | C37: =CI!#REF! -> #REF! | D37: =CI!#REF! -> #REF! | E37: PCS | F37: =CI!#REF! -> #REF! | G37: =CI!#REF! -> #REF!
A38: =CI!#REF! -> #REF! | B38: =CI!#REF! -> #REF! | C38: =CI!#REF! -> #REF! | D38: =CI!#REF! -> #REF! | E38: PCS | F38: =CI!#REF! -> #REF! | G38: =CI!#REF! -> #REF!
A39: =CI!#REF! -> #REF! | B39: =CI!#REF! -> #REF! | C39: =CI!#REF! -> #REF! | D39: =CI!#REF! -> #REF! | E39: PCS | F39: =CI!#REF! -> #REF! | G39: =CI!#REF! -> #REF!
A40: =CI!#REF! -> #REF! | B40: =CI!#REF! -> #REF! | C40: =CI!#REF! -> #REF! | D40: =CI!#REF! -> #REF! | E40: PCS | F40: =CI!#REF! -> #REF! | G40: =CI!#REF! -> #REF!
A41: =CI!#REF! -> #REF! | B41: =CI!#REF! -> #REF! | C41: =CI!#REF! -> #REF! | D41: =CI!#REF! -> #REF! | E41: PCS | F41: =CI!#REF! -> #REF! | G41: =CI!#REF! -> #REF!
A42: =CI!#REF! -> #REF! | B42: =CI!#REF! -> #REF! | C42: =CI!#REF! -> #REF! | D42: =CI!#REF! -> #REF! | E42: PCS | F42: =CI!#REF! -> #REF! | G42: =CI!#REF! -> #REF!
A43: =CI!#REF! -> #REF! | B43: =CI!#REF! -> #REF! | C43: =CI!#REF! -> #REF! | D43: =CI!#REF! -> #REF! | E43: PCS | F43: =CI!#REF! -> #REF! | G43: =CI!#REF! -> #REF!
B45: Total | D45: =SUM(D28:D43) -> #REF! | G45: =SUM(G28:G43) -> #REF!
A46: * Advising Bank : | B46: PT. BANK KEB HANA INDONESIA
B47: 1225-509-8721
A49: *Beneficiary : | B49: PT ZINUS GLOBAL INDONEISA
B50: JI Raya Parung No.68, Kel. Curug, Kec. Gunug Sindur, Kab. Bogor, Prop. Jawa Barat,Indonesia
...

Sheet PO
A1: Purchase Order
A2: * Date : | D2: * Name of Supplier : | E2: Zinus Global Indonesia
A3: * Buyer : | B3: ZINUS,INC. | D3: * Name of LC Beneficiary :
D4: *Address of T/T Beneficiary : | E4: Zinus Global Indonesia
A5: * Payment Terms with buyer : | D5: * Name of Advising Bank : | E5: JI Raya Parung No.68, Kel. Curug, Kec. Gunug Sindur, Kab. Bogor, Prop. Jawa Barat,Indonesia
A6: * Contact NO. | B6: =CI!I4 -> ID2608-9295 | D6: * Name of Advising Bank : | E6: PT. BANK KEB HANA INDONESIA
D7: * Account No. : | E7: 1225-509-8721
A8: * Delivery Terms : | B8: FOB Indonesia | D8: * Payment Term | E8: AT 90 DAYS AFTER B/L DATE
A9: * Shipment From : | B9: Indonesia | D9: * Contact Person : | E9: Joe Song
A10: * Ship to : | B10: =CI!C24 -> OAKLAND,CA | D10: * TEL
D11: * FAX
A13: Buyer PO # | B13: Goods Descriptions | E13: Latest Shipdate | F13: Quantity (pieces) | G13: Price | H13: Total Amount | I13: Remarks
A14: =CI!C29 -> TIN60185 | B14: =CI!H29 -> 0 | F14: =CI!K29 -> PCS | G14: =CI!M29 -> 2116.2 | H14: =G14*F14 -> #VALUE!
A15: =CI!C30 -> TIN60185 | B15: =CI!H30 -> 0 | F15: =CI!K30 -> PCS | G15: =CI!M30 -> 18638.22 | H15: =G15*F15 -> #VALUE!
A16: =CI!C31 -> TIN60185 | B16: =CI!H31 -> 0 | F16: =CI!K31 -> PCS | G16: =CI!M31 -> 2736.2 | H16: =G16*F16 -> #VALUE!
A17: =CI!C37 -> 0 | B17: =CI!H37 -> 0 | F17: =CI!K37 -> 0 | G17: =CI!M37 -> 0 | H17: =G17*F17 -> 0
A18: =CI!#REF! -> #REF! | B18: =CI!#REF! -> #REF! | F18: =CI!#REF! -> #REF! | G18: =CI!#REF! -> #REF! | H18: =G18*F18 -> #REF!
A19: =CI!#REF! -> #REF! | B19: =CI!#REF! -> #REF! | F19: =CI!#REF! -> #REF! | G19: =CI!#REF! -> #REF! | H19: =G19*F19 -> #REF!
A20: =CI!#REF! -> #REF! | B20: =CI!#REF! -> #REF! | F20: =CI!#REF! -> #REF! | G20: =CI!#REF! -> #REF! | H20: =G20*F20 -> #REF!
A21: =CI!#REF! -> #REF! | B21: =CI!#REF! -> #REF! | F21: =CI!#REF! -> #REF! | G21: =CI!#REF! -> #REF! | H21: =G21*F21 -> #REF!
A22: =CI!#REF! -> #REF! | B22: =CI!#REF! -> #REF! | F22: =CI!#REF! -> #REF! | G22: =CI!#REF! -> #REF! | H22: =G22*F22 -> #REF!
A23: =CI!#REF! -> #REF! | B23: =CI!#REF! -> #REF! | F23: =CI!#REF! -> #REF! | G23: =CI!#REF! -> #REF! | H23: =G23*F23 -> #REF!
A24: =CI!#REF! -> #REF! | B24: =CI!#REF! -> #REF! | F24: =CI!#REF! -> #REF! | G24: =CI!#REF! -> #REF! | H24: =G24*F24 -> #REF!
A25: =CI!#REF! -> #REF! | B25: =CI!#REF! -> #REF! | F25: =CI!#REF! -> #REF! | G25: =CI!#REF! -> #REF! | H25: =G25*F25 -> #REF!
A26: =CI!#REF! -> #REF! | B26: =CI!#REF! -> #REF! | F26: =CI!#REF! -> #REF! | G26: =CI!#REF! -> #REF! | H26: =G26*F26 -> #REF!
A27: =CI!#REF! -> #REF! | B27: =CI!#REF! -> #REF! | F27: =CI!#REF! -> #REF! | G27: =CI!#REF! -> #REF! | H27: =G27*F27 -> #REF!
A28: =CI!#REF! -> #REF! | B28: =CI!#REF! -> #REF! | F28: =CI!#REF! -> #REF! | G28: =CI!#REF! -> #REF! | H28: =G28*F28 -> #REF!
A29: =CI!#REF! -> #REF! | B29: =CI!#REF! -> #REF! | F29: =CI!#REF! -> #REF! | G29: =CI!#REF! -> #REF! | H29: =G29*F29 -> #REF!
A33: Total | F33: =SUM(F14:F32) -> #REF! | H33: =SUM(H14:H32) -> #VALUE!
A39: Zinus Inc. Korea
A40: 8F, 10 (AMIGO-TOWER) YATAP-RO,
A41: 81 BEON-GIL, BUNDANG-GU, SEONGNAM-SI,
A42: GYUNGGI-DO, KOREA | F42: Signature
G43: PT ZINUS GLOBAL INDONEISA
