Workbook
Name _3._Document: '[1]1.Global Setting'!#REF!
Name _3._Document: '[1]1.Global Setting'!#REF!
Name _4._Cost_center___Profit_Center: '[1]1.Global Setting'!#REF!
Name _4._Cost_center___Profit_Center: '[1]1.Global Setting'!#REF!
Name _5._Tax: '[1]1.Global Setting'!#REF!
Name _5._Tax: '[1]1.Global Setting'!#REF!
Name ☞: '[2]1.Global Setting'!#REF!
Name ☞: '[2]1.Global Setting'!#REF!
Name a: #REF!
Name a: #REF!
Name application: #REF!
Name application: #REF!
Name ETC: #REF!
Name ETC: #REF!
Name flow: #REF!
Name flow: #REF!
Name head: #REF!
Name head: #REF!
Name Keetsa_Pillows: '[4]Materials List'!#REF!
Name Keetsa_Pillows: '[4]Materials List'!#REF!
Name kmart: '[5]Materials List'!#REF!
Name kmart: '[5]Materials List'!#REF!
Name kmart: '[6]Materials List'!#REF!
Name MARK: '[4]Materials List'!#REF!
Name MARK: '[4]Materials List'!#REF!
Name MARK2: #REF!
Name MARK2: #REF!
Name RATE1: '[7]WMT-150Q'!$F$13
Name tony: #REF!
Name tony: #REF!
Name twort000: '[1]1.Global Setting'!$AB$66
Name ZIPPERB: #N/A
Name 暗暗: [8]负债表!$G$1

Sheet CM
A1: CONTAINER MANIFEST
J2: PAGE.1
A3: SHIPPER: PT. Zinus Global Indonesia
A4: CONSIGNEE: ZINUS,INC (USA)
A5: CONTAINER NO. | D5: CONTAINER SIZE: | E5: SEAL NO. | G5: SHIPPING LINE
D6: 20' 40'S 40RH 40'H 45'
D7: [ ] [ X ] [ ] [ ] [ ]
A8: VESSEL / VOY. | D8: LOADING PORT | E8: DISCHARGE PORT / DESTINATION | G8: SAILING DATE | J8: ARRIVAL DATE
D9: JAKARTA, INDONESIA | E9: =#REF! -> #REF! | G9: JULY. XX, 2019 | J9: AUGT. XX, 2019
A11: PURCHASE ORDER NO. | B11: STYLE NO | C11: UPC NO | D11: BRIEF DESCRIPTION | E11: NO. OF | F11: MEASUREMENT | G11: GROSS WEIGHT | H11: Quantity | I11: SAMPLE | J11: B/L NO.
E12: CARTONS | F12: CBM | G12: KGS | H12: PCS | I12: CTN. NO.
A13: =#REF! -> #REF! | B13: XX | C13: =#REF! -> #REF! | D13: =#REF! -> #REF! | E13: =#REF! -> #REF! | F13: 58.344 | G13: 6342.7 | H13: =E13 -> #REF!
D15: TOTAL:
A16: SHIPPER'S CO. CHOP &
A17: AUTHORIZED SIGNATURE:
A19: PO DATE : MAY. XX,2019
A20: ETD : JULY. XX,2019

Sheet  CI
B2: COMMERCIAL INVOICE
B3: SHIPPER | G3: Invoice No. and Date
B4: PT ZINUS DREAM INDONESIA | G4: ID2609-9297 | K4: 46289
B5: JL. RAYA SERANG KM. 12 RT. 01 RW. 05 | G5: L/C No. and Date
B6: KP. GEBANG DESA/KEL. SUKADAMAI, KEC. CIKUPA, KAB. TANGERANG | G6: T/T PAYMENT
B7: BANTEN, INDONESIA
B9: Consignee : | G9: Buyer (if other than consignee)
B10: AMAZON.COM SERVICES LLC | G10: ZINUS INC,
B11: 410 TERRY AVE. NORTH SEATTLE, WA 98109-5210 | G11: 8F, 10 (AMIGO-TOWER) YATAP-RO,
B12: UNITED STATES | G12: 81 BEON-GIL BUNDANG-GU, SEONGNAM-SI, GYUNGGI-DO, KOREA
B14: Notify : | G14: Other Reference
B15: DAMCO CUSTOMS SERVICES INC. | G15: *COUNTRY OF ORIGIN : INDONESIA
B16: ZINUSNAMCHB@LNS.MAERSK.COM | G16: PO# | H16: 8GHY1D8T
B17: 9300 ARROWPOINT BOULEVARD BUILDING1 | G17: DO# | H17: EBKG18575113
B18: CHARLOTTE, NC 28273 | G18: BL# | H18: MEDUKU810470
B20: Departure : | G20: Terms of delivery and payment
B21: 46296 | G21: FOB INDONESIA
B22: Vessel / Flight | E22: From / Port Of Loading : | G22: T/T 90 days after Document Date
B23: MSC SINGAPORE IV XF640R | E23: Jakarta, INDONESIA
B24: To : | C24: LONG BEACH, CA, UNITED STATES
B25: =Shipping Mark=
B27: HS CODE | C27: PO# | D27: ITEM# | E27: F CODE | F27: DESCRIPTION | I27: Quantity | K27: Unit Price | L27: Amount | M27: Total N.W
B29: 9404.21.20 | C29: 8GHY1D8T | D29: ZU-MFGN1YZI-12K | E29: F.MFG.12K.002.AD | F29: 12In Mygel Foam Mattress King | I29: 350 | J29: PCS | K29: 101.78 | L29: =K29*I29 -> 35623 | M29: 12383 | N29: =C29&D29&E29 -> 8GHY1D8TZU-MFGN1YZI-12KF.MFG.12K.002.AD | O29: =D29&E29 -> ZU-MFGN1YZI-12KF.MFG.12K.002.AD | P29: =C29&D29 -> 8GHY1D8TZU-MFGN1YZI-12K
B30: 9404.21.20 | C30: 8GHY1D8T | D30: ZU-MFGN1YZI-12K | E30: F.MFG.12K.002.AD | F30: 12In Mygel Foam Mattress King | I30: 350 | J30: PCS | K30: 101.78 | L30: =K30*I30 -> 35623 | M30: 12383 | N30: =C30&D30&E30 -> 8GHY1D8TZU-MFGN1YZI-12KF.MFG.12K.002.AD | O30: =D30&E30 -> ZU-MFGN1YZI-12KF.MFG.12K.002.AD | P30: =C30&D30 -> 8GHY1D8TZU-MFGN1YZI-12K
B31: 9404.21.20 | C31: 8GHY1D8T | D31: ZU-MFMA1ZZI-10X | E31: F.MFM.10X.007.AD | F31: 10IN GREEN TEA FOAM MATTRESS TWIN XL | I31: 285 | J31: PCS | K31: 50.35 | L31: =K31*I31 -> 14349.75 | M31: 4562.85 | N31: =C31&D31&E31 -> 8GHY1D8TZU-MFMA1ZZI-10XF.MFM.10X.007.AD | O31: =D31&E31 -> ZU-MFMA1ZZI-10XF.MFM.10X.007.AD | P31: =C31&D31 -> 8GHY1D8TZU-MFMA1ZZI-10X
B32: 9404.21.20 | C32: 8GHY1D8T | D32: ZU-MFMA1ZZI-05T | E32: F.MFM.05T.007.AD | F32: 5in Green Tea Foam Mattress Twin | I32: 585 | J32: PCS | K32: 23.66 | L32: =K32*I32 -> 13841.1 | M32: 5440.5 | N32: =C32&D32&E32 -> 8GHY1D8TZU-MFMA1ZZI-05TF.MFM.05T.007.AD | O32: =D32&E32 -> ZU-MFMA1ZZI-05TF.MFM.05T.007.AD | P32: =C32&D32 -> 8GHY1D8TZU-MFMA1ZZI-05T
B33: 9404.21.20 | C33: 8GHY1D8T | D33: ZU-MFMA1ZZI-12T | E33: F.MFM.12T.006.AD | F33: 12In Green Tea Foam Mattress Twin | I33: 13 | J33: PCS | K33: 63.2 | L33: =K33*I33 -> 821.6 | M33: 226.46 | N33: =C33&D33&E33 -> 8GHY1D8TZU-MFMA1ZZI-12TF.MFM.12T.006.AD | O33: =D33&E33 -> ZU-MFMA1ZZI-12TF.MFM.12T.006.AD | P33: =C33&D33 -> 8GHY1D8TZU-MFMA1ZZI-12T
B34: 9404.21.20 | C34: 8GHY1D8T | D34: ZU-MFMA1RZI-10T | E34: F.MFM.10T.014.AD | F34: 10In Green Tea Essential Twin Mattress | I34: 146 | J34: PCS | K34: 38.93 | L34: =K34*I34 -> 5683.78 | M34: 2061.52 | N34: =C34&D34&E34 -> 8GHY1D8TZU-MFMA1RZI-10TF.MFM.10T.014.AD | O34: =D34&E34 -> ZU-MFMA1RZI-10TF.MFM.10T.014.AD | P34: =C34&D34 -> 8GHY1D8TZU-MFMA1RZI-10T
B35: 9404.21.20 | C35: 8GHY1D8T | D35: ZU-MFMA1OZI-05T | E35: F.MFM.05T.008.AD | F35: 5In Cooling Essential Twin Mattress | I35: 101 | J35: PCS | K35: 23.95 | L35: =K35*I35 -> 2418.95 | M35: 959.5 | N35: =C35&D35&E35 -> 8GHY1D8TZU-MFMA1OZI-05TF.MFM.05T.008.AD | O35: =D35&E35 -> ZU-MFMA1OZI-05TF.MFM.05T.008.AD | P35: =C35&D35 -> 8GHY1D8TZU-MFMA1OZI-05T
B36: 9404.21.20 | C36: 8GHY1D8T | D36: ZU-MFMA1ZZI-06Q | E36: F.MFM.06Q.007.AD | F36: 6In Green Tea Foam Mattress Queen | I36: 515 | J36: PCS | K36: 45.51 | L36: =K36*I36 -> 23437.65 | M36: 7714.7 | N36: =C36&D36&E36 -> 8GHY1D8TZU-MFMA1ZZI-06QF.MFM.06Q.007.AD | O36: =D36&E36 -> ZU-MFMA1ZZI-06QF.MFM.06Q.007.AD | P36: =C36&D36 -> 8GHY1D8TZU-MFMA1ZZI-06Q
B37: 9404.21.20 | C37: 8GHY1D8T | D37: ZU-MFMA1ZZI-10T | E37: F.MFM.10T.007.AD | F37: 10In Green Tea Foam Mattress Twin | I37: 360 | J37: PCS | K37: 55.24 | L37: =K37*I37 -> 19886.4 | M37: 5320.8 | N37: =C37&D37&E37 -> 8GHY1D8TZU-MFMA1ZZI-10TF.MFM.10T.007.AD | O37: =D37&E37 -> ZU-MFMA1ZZI-10TF.MFM.10T.007.AD | P37: =C37&D37 -> 8GHY1D8TZU-MFMA1ZZI-10T
B38: 9404.21.20 | C38: 8GHY1D8T | D38: ZU-MFMA1ZZI-10F | E38: F.MFM.10F.007.AD | F38: 10In Green Tea Foam Mattress Full | I38: 295 | J38: PCS | K38: 62.06 | L38: =K38*I38 -> 18307.7 | M38: 5997.35 | N38: =C38&D38&E38 -> 8GHY1D8TZU-MFMA1ZZI-10FF.MFM.10F.007.AD | O38: =D38&E38 -> ZU-MFMA1ZZI-10FF.MFM.10F.007.AD | P38: =C38&D38 -> 8GHY1D8TZU-MFMA1ZZI-10F
B39: 9404.21.20 | C39: 8GHY1D8T | D39: ZU-MFGN1YZI-12K | E39: F.MFG.12K.002.AD | F39: 12In Mygel Foam Mattress King | I39: 44 | J39: PCS | K39: 101.78 | L39: =K39*I39 -> 4478.32 | M39: 1556.72 | N39: =C39&D39&E39 -> 8GHY1D8TZU-MFGN1YZI-12KF.MFG.12K.002.AD | O39: =D39&E39 -> ZU-MFGN1YZI-12KF.MFG.12K.002.AD | P39: =C39&D39 -> 8GHY1D8TZU-MFGN1YZI-12K
B40: 9404.21.20 | C40: 8GHY1D8T | D40: ZU-MFMA1ZZI-10T | E40: F.MFM.10T.007.AD | F40: 10In Green Tea Foam Mattress Twin | I40: 82 | J40: PCS | K40: 55.24 | L40: =K40*I40 -> 4529.68 | M40: 1211.96 | N40: =C40&D40&E40 -> 8GHY1D8TZU-MFMA1ZZI-10TF.MFM.10T.007.AD | O40: =D40&E40 -> ZU-MFMA1ZZI-10TF.MFM.10T.007.AD | P40: =C40&D40 -> 8GHY1D8TZU-MFMA1ZZI-10T
... B42: 9404.21.20 | C42: 8GHY1D8T | D42: ZU-MFMA1ZZI-08T | E42: F.MFM.08T.008.AD | F42: 8In Green Tea Foam Mattress Twin | I42: 87 | J42: PCS | K42: 35.93 | L42: =K42*I42 -> 3125.91 | M42: 1053.57 | N42: =C42&D42&E42 -> 8GHY1D8TZU-MFMA1ZZI-08TF.MFM.08T.008.AD | O42: =D42&E42 -> ZU-MFMA1ZZI-08TF.MFM.08T.008.AD | P42: =C42&D42 -> 8GHY1D8TZU-MFMA1ZZI-08T
N44: =C44&D44&E44 | O44: =D44&E44 | P44: =C44&D44
N45: =C45&D45&E45 | O45: =D45&E45 | P45: =C45&D45
N46: =C46&D46&E46 | O46: =D46&E46 | P46: =C46&D46
N47: =C47&D47&E47 | O47: =D47&E47 | P47: =C47&D47
N48: =C48&D48&E48 | O48: =D48&E48 | P48: =C48&D48
...

Sheet  PL
B2: PACKING LIST
B3: Shipper | H3: Invoice No. and Date
B4: =' CI'!B4 -> PT ZINUS DREAM INDONESIA | H4: =' CI'!G4 -> ID2609-9297 | J4: =' CI'!K4 -> 46289
B5: =' CI'!B5 -> JL. RAYA SERANG KM. 12 RT. 01 RW. 05 | H5: L/C No. and Date
B6: =' CI'!B6 -> KP. GEBANG DESA/KEL. SUKADAMAI, KEC. CIKUPA, KAB. TANGERANG | H6: =' CI'!G6 -> T/T PAYMENT
B7: =' CI'!B7 -> BANTEN, INDONESIA
B9: Consignee : | H9: Buyer (if other than consignee)
B10: =' CI'!B10 -> AMAZON.COM SERVICES LLC | H10: =' CI'!G10 -> ZINUS INC,
B11: =' CI'!B11 -> 410 TERRY AVE. NORTH SEATTLE, WA 98109-5210 | H11: =' CI'!G11 -> 8F, 10 (AMIGO-TOWER) YATAP-RO,
B12: =' CI'!B12 -> UNITED STATES | H12: =' CI'!G12 -> 81 BEON-GIL BUNDANG-GU, SEONGNAM-SI, GYUNGGI-DO, KOREA
B14: Notify : | H14: Other Reference
B15: =' CI'!B15 -> DAMCO CUSTOMS SERVICES INC. | H15: =' CI'!G15 -> *COUNTRY OF ORIGIN : INDONESIA
B16: =' CI'!B16 -> ZINUSNAMCHB@LNS.MAERSK.COM | H16: =' CI'!G16 -> PO# | I16: =' CI'!H16 -> 8GHY1D8T
B17: =' CI'!B17 -> 9300 ARROWPOINT BOULEVARD BUILDING1 | H17: =' CI'!G17 -> DO# | I17: =' CI'!H17 -> EBKG18575113
B18: =' CI'!B18 -> CHARLOTTE, NC 28273 | H18: =' CI'!G18 -> BL# | I18: =' CI'!H18 -> MEDUKU810470
B20: Departure Date : | H20: Terms of delivery and payment
B21: =' CI'!B21 -> 46296 | H21: =' CI'!G21 -> FOB INDONESIA | XFA21: =SUM(B21:XEZ21) -> 46296
B22: Vessel / Flight / Voyage : | E22: From / Port Of Loading : | H22: T/T 90 days after Document Date
B23: =' CI'!B23 -> MSC SINGAPORE IV XF640R | E23: Jakarta, INDONESIA
B24: To : | C24: =' CI'!C24 -> LONG BEACH, CA, UNITED STATES
B25: = Shipping MARK | D25: No. & Kind of Pkgs; Goods Description | G25: Net Weight | I25: Gross Weight | J25: Measurement
G27: =J49 -> 68149.69 | I27: 77536.4 | J27: 368.784
C29: PO# | D29: DESCRIPTION | F29: QTY | I29: NW/PCS | J29: Total NW
C30: =' CI'!C29 -> 8GHY1D8T | D30: =' CI'!F29 -> 12In Mygel Foam Mattress King | F30: =' CI'!I29 -> 350 | G30: =' CI'!I29 -> 350 | I30: 35.38 | J30: =I30*G30 -> 12383 | XFA30: =SUM(B30:XEZ30) -> 13118.38
C31: =' CI'!C30 -> 8GHY1D8T | D31: =' CI'!F30 -> 12In Mygel Foam Mattress King | F31: =' CI'!I30 -> 350 | G31: =' CI'!I30 -> 350 | I31: 35.38 | J31: =I31*G31 -> 12383
C32: =' CI'!C31 -> 8GHY1D8T | D32: =' CI'!F31 -> 10IN GREEN TEA FOAM MATTRESS TWIN XL | F32: =' CI'!I31 -> 285 | G32: =' CI'!I31 -> 285 | I32: 16.01 | J32: =I32*G32 -> 4562.85
C33: =' CI'!C32 -> 8GHY1D8T | D33: =' CI'!F32 -> 5in Green Tea Foam Mattress Twin | F33: =' CI'!I32 -> 585 | G33: =' CI'!I32 -> 585 | I33: 9.3 | J33: =I33*G33 -> 5440.5
C34: =' CI'!C33 -> 8GHY1D8T | D34: =' CI'!F33 -> 12In Green Tea Foam Mattress Twin | F34: =' CI'!I33 -> 13 | G34: =' CI'!I33 -> 13 | I34: 17.42 | J34: =I34*G34 -> 226.46
C35: =' CI'!C34 -> 8GHY1D8T | D35: =' CI'!F34 -> 10In Green Tea Essential Twin Mattress | F35: =' CI'!I34 -> 146 | G35: =' CI'!I34 -> 146 | I35: 14.12 | J35: =I35*G35 -> 2061.52
C36: =' CI'!C35 -> 8GHY1D8T | D36: =' CI'!F35 -> 5In Cooling Essential Twin Mattress | F36: =' CI'!I35 -> 101 | G36: =' CI'!I35 -> 101 | I36: 9.5 | J36: =I36*G36 -> 959.5
C37: =' CI'!C36 -> 8GHY1D8T | D37: =' CI'!F36 -> 6In Green Tea Foam Mattress Queen | F37: =' CI'!I36 -> 515 | G37: =' CI'!I36 -> 515 | I37: 14.98 | J37: =I37*G37 -> 7714.7
C38: =' CI'!C37 -> 8GHY1D8T | D38: =' CI'!F37 -> 10In Green Tea Foam Mattress Twin | F38: =' CI'!I37 -> 360 | G38: =' CI'!I37 -> 360 | I38: 14.78 | J38: =I38*G38 -> 5320.8
C39: =' CI'!C38 -> 8GHY1D8T | D39: =' CI'!F38 -> 10In Green Tea Foam Mattress Full | F39: =' CI'!I38 -> 295 | G39: =' CI'!I38 -> 295 | I39: 20.33 | J39: =I39*G39 -> 5997.35
C40: =' CI'!C39 -> 8GHY1D8T | D40: =' CI'!F39 -> 12In Mygel Foam Mattress King | F40: =' CI'!I39 -> 44 | G40: =' CI'!I39 -> 44 | I40: 35.38 | J40: =I40*G40 -> 1556.72
C41: =' CI'!C40 -> 8GHY1D8T | D41: =' CI'!F40 -> 10In Green Tea Foam Mattress Twin | F41: =' CI'!I40 -> 82 | G41: =' CI'!I40 -> 82 | I41: 14.78 | J41: =I41*G41 -> 1211.96
C42: =' CI'!C41 -> 8GHY1D8T | D42: =' CI'!F41 -> 10In Mygel Foam Mattress Full | F42: =' CI'!I41 -> 361 | G42: =' CI'!I41 -> 361 | I42: 20.16 | J42: =I42*G42 -> 7277.76
C43: =' CI'!C42 -> 8GHY1D8T | D43: =' CI'!F42 -> 8In Green Tea Foam Mattress Twin | F43: =' CI'!I42 -> 87 | G43: =' CI'!I42 -> 87 | I43: 12.11 | J43: =I43*G43 -> 1053.57
E49: TOTAL : | F49: =SUM(F30:F48) -> 3574 | G49: =SUM(G30:G48) -> 3574 | J49: =SUM(J30:J48) -> 68149.69 | XFA49: =SUM(B49:XEZ49) -> 75297.69
I92: Signed by,
C94: WE DECLARE THAT THE SHIPMENT CONTAINS NO SOLID WOOD PACKING MATERIALS.
